Workbook
Name Alcohol_and_Tobacco: Reference!$H$2:$H$3
Name Clothing_and_Footwear: Reference!$I$2:$I$5
Name DS_Country_List: Reference!$C$2:$C$206
Name DS_Currency_List: Reference!$D$2:$D$206
Name DSCountry: 'Data Table'!$C$3
Name Education: Reference!$J$2:$J$16
Name Food_and_Non_Alcoholic_Beverages: Reference!$K$2:$K$3
Name Furniture_Household_and_Routine_Home_Maintenance: Reference!$L$2:$L$9
Name FXRatesTable: 'FX Rates'!$A$1:$BQ$152
Name GroupList: [1]Reference!$N$1:$N$14
Name Health_Out_of_Pocket: Reference!$M$2:$M$6
Name Housing: Reference!$N$2:$N$3
Name Information_and_Communication: Reference!$O$2:$O$3
Name InsideOutside: [1]Reference!$K$1:$K$2
Name InsideOutsideList: Reference!$E$2:$E$3
Name Insurance_and_Financial_Services: Reference!$P$2:$P$5
Name ISOCodeList: 'FX Rates'!$A$2:$A$152
Name ISOList: [1]Reference!$AH$1:$AH$152
Name Item_List: Reference!$Y$2:$Y$80
Name Item_List_Number: Reference!$W$2:$W$80
Name ItemCategoryList: Reference!$G$2:$G$15
Name Month_List: Reference!$B$2:$B$13
Name Month_Number: Reference!$A$2:$A$13
Name Other: Reference!$Q$2:$Q$4
Name Personal_and_Miscellaneous_Goods_and_Services: Reference!$R$2:$R$8
Name Recreation_and_Culture: Reference!$S$2:$S$11
Name Restaurants_and_Accommodation_Services: Reference!$T$2:$T$4
Name Summary_View_Explainer: Reference!$AB$2:$AB$7
Name Summary_View_List: Reference!$AA$2:$AA$7
Name SummaryTableToggleTable: 'Summary Table Toggle'!$B$4:$H$18
Name SummaryToggleAllTime: 'Summary Table Toggle'!$E$4:$E$18
Name SummaryToggleAllTimeLC: 'Summary Table Toggle'!$F$4:$F$18
Name SummaryToggleCategory: 'Summary Table Toggle'!$B$4:$B$18
Name SummaryToggleEstimatedMonth: 'Summary Table Toggle'!$G$4:$G$18
Name SummaryToggleEstimatedMonthLC: 'Summary Table Toggle'!$H$4:$H$18
Name SummaryTogglePast30: 'Summary Table Toggle'!$C$4:$C$18
Name SummaryTogglePast30LC: 'Summary Table Toggle'!$D$4:$D$18
Name SummaryView: Summary!$C$4
Name Time_Span: Reference!$X$2:$X$80
Name Transport: Reference!$U$2:$U$13

Sheet Data Table
D1: Instructions 1. Indicate the country of duty station. 2. Record expenses in the yellow fields of the table below. The item category must be specified before selecting the item subcategory. 3. The summary tab displays a summary of expenses with the option of three different views. 4. The "Monthly Expenses", "Yearly and Education Expenses" and "Infrequent Expenses" tabs display expenses formatted in accordance with the cost-of-living survey.
C2: COUNTRY OF DUTY STATION
C3: Australia
C4: =IF(ISBLANK(DSCountry),"Select duty station above","Local Currency: "&(_xlfn.XLOOKUP(DSCountry,DS_Country_List,DS_Currency_List))) -> Local Currency: AUD
D6: ICSC Electronic Diary: Itemized List of All Expenditures | G6: ="Exchange rate conversions are based on history of UN Treasury rates from Jan 2021 through "&_xlfn.XLOOKUP(MONTH(MAX('FX Rates'!1:1)),Month_Number,Month_List)& " "&YEAR(MAX('FX Rates'!1:1)) -> Exchange rate conversions are based on history of UN Treasury rates from Jan 2021 through Aug 2026
B7: DATE | C7: ITEM CATEGORY | D7: ITEM SUBCATEGORY | E7: ITEM DESCRIPTION (Optional) | F7: Inside/Outside Duty Station | G7: AMOUNT | H7: CURRENCY | I7: TIME SPAN | J7: AMOUNT in USD
B8: 46249 | C8: Food and Non Alcoholic Beverages | D8: Food Purchased in Markets | E8: Example | F8: Inside | G8: 200 | H8: AUD | I8: =IF(ISBLANK($D8),"",_xlfn.XLOOKUP($D8,Item_List,Time_Span,"",0)) -> M | J8: =IF(ISBLANK($H8),"",IF(VLOOKUP($H8,'FX Rates'!$A$1:$BQ$152,_xlfn.XMATCH($B8,'FX Rates'!$A$1:$BQ$1,-1,1),0)=0,"No Exch Rate Data",IF($G8=0,"",$G8/VLOOKUP($H8,'FX Rates'!$A$1:$BQ$152,_xlfn.XMATCH($B8,'FX Rates'!$A$1:$BQ$1,-1,1),0)))) -> 141.14326
I9: =IF(ISBLANK($D9),"",_xlfn.XLOOKUP($D9,Item_List,Time_Span,"",0)) | J9: =IF(ISBLANK($H9),"",IF(VLOOKUP($H9,'FX Rates'!$A$1:$BQ$152,_xlfn.XMATCH($B9,'FX Rates'!$A$1:$BQ$1,-1,1),0)=0,"No Exch Rate Data",IF($G9=0,"",$G9/VLOOKUP($H9,'FX Rates'!$A$1:$BQ$152,_xlfn.XMATCH($B9,'FX Rates'!$A$1:$BQ$1,-1,1),0))))
I10: =IF(ISBLANK($D10),"",_xlfn.XLOOKUP($D10,Item_List,Time_Span,"",0)) | J10: =IF(ISBLANK($H10),"",IF(VLOOKUP($H10,'FX Rates'!$A$1:$BQ$152,_xlfn.XMATCH($B10,'FX Rates'!$A$1:$BQ$1,-1,1),0)=0,"No Exch Rate Data",IF($G10=0,"",$G10/VLOOKUP($H10,'FX Rates'!$A$1:$BQ$152,_xlfn.XMATCH($B10,'FX Rates'!$A$1:$BQ$1,-1,1),0))))
I11: =IF(ISBLANK($D11),"",_xlfn.XLOOKUP($D11,Item_List,Time_Span,"",0)) | J11: =IF(ISBLANK($H11),"",IF(VLOOKUP($H11,'FX Rates'!$A$1:$BQ$152,_xlfn.XMATCH($B11,'FX Rates'!$A$1:$BQ$1,-1,1),0)=0,"No Exch Rate Data",IF($G11=0,"",$G11/VLOOKUP($H11,'FX Rates'!$A$1:$BQ$152,_xlfn.XMATCH($B11,'FX Rates'!$A$1:$BQ$1,-1,1),0))))
I12: =IF(ISBLANK($D12),"",_xlfn.XLOOKUP($D12,Item_List,Time_Span,"",0)) | J12: =IF(ISBLANK($H12),"",IF(VLOOKUP($H12,'FX Rates'!$A$1:$BQ$152,_xlfn.XMATCH($B12,'FX Rates'!$A$1:$BQ$1,-1,1),0)=0,"No Exch Rate Data",IF($G12=0,"",$G12/VLOOKUP($H12,'FX Rates'!$A$1:$BQ$152,_xlfn.XMATCH($B12,'FX Rates'!$A$1:$BQ$1,-1,1),0))))
I13: =IF(ISBLANK($D13),"",_xlfn.XLOOKUP($D13,Item_List,Time_Span,"",0)) | J13: =IF(ISBLANK($H13),"",IF(VLOOKUP($H13,'FX Rates'!$A$1:$BQ$152,_xlfn.XMATCH($B13,'FX Rates'!$A$1:$BQ$1,-1,1),0)=0,"No Exch Rate Data",IF($G13=0,"",$G13/VLOOKUP($H13,'FX Rates'!$A$1:$BQ$152,_xlfn.XMATCH($B13,'FX Rates'!$A$1:$BQ$1,-1,1),0))))
I14: =IF(ISBLANK($D14),"",_xlfn.XLOOKUP($D14,Item_List,Time_Span,"",0)) | J14: =IF(ISBLANK($H14),"",IF(VLOOKUP($H14,'FX Rates'!$A$1:$BQ$152,_xlfn.XMATCH($B14,'FX Rates'!$A$1:$BQ$1,-1,1),0)=0,"No Exch Rate Data",IF($G14=0,"",$G14/VLOOKUP($H14,'FX Rates'!$A$1:$BQ$152,_xlfn.XMATCH($B14,'FX Rates'!$A$1:$BQ$1,-1,1),0))))
I15: =IF(ISBLANK($D15),"",_xlfn.XLOOKUP($D15,Item_List,Time_Span,"",0)) | J15: =IF(ISBLANK($H15),"",IF(VLOOKUP($H15,'FX Rates'!$A$1:$BQ$152,_xlfn.XMATCH($B15,'FX Rates'!$A$1:$BQ$1,-1,1),0)=0,"No Exch Rate Data",IF($G15=0,"",$G15/VLOOKUP($H15,'FX Rates'!$A$1:$BQ$152,_xlfn.XMATCH($B15,'FX Rates'!$A$1:$BQ$1,-1,1),0))))
I16: =IF(ISBLANK($D16),"",_xlfn.XLOOKUP($D16,Item_List,Time_Span,"",0)) | J16: =IF(ISBLANK($H16),"",IF(VLOOKUP($H16,'FX Rates'!$A$1:$BQ$152,_xlfn.XMATCH($B16,'FX Rates'!$A$1:$BQ$1,-1,1),0)=0,"No Exch Rate Data",IF($G16=0,"",$G16/VLOOKUP($H16,'FX Rates'!$A$1:$BQ$152,_xlfn.XMATCH($B16,'FX Rates'!$A$1:$BQ$1,-1,1),0))))
I17: =IF(ISBLANK($D17),"",_xlfn.XLOOKUP($D17,Item_List,Time_Span,"",0)) | J17: =IF(ISBLANK($H17),"",IF(VLOOKUP($H17,'FX Rates'!$A$1:$BQ$152,_xlfn.XMATCH($B17,'FX Rates'!$A$1:$BQ$1,-1,1),0)=0,"No Exch Rate Data",IF($G17=0,"",$G17/VLOOKUP($H17,'FX Rates'!$A$1:$BQ$152,_xlfn.XMATCH($B17,'FX Rates'!$A$1:$BQ$1,-1,1),0))))
I18: =IF(ISBLANK($D18),"",_xlfn.XLOOKUP($D18,Item_List,Time_Span,"",0)) | J18: =IF(ISBLANK($H18),"",IF(VLOOKUP($H18,'FX Rates'!$A$1:$BQ$152,_xlfn.XMATCH($B18,'FX Rates'!$A$1:$BQ$1,-1,1),0)=0,"No Exch Rate Data",IF($G18=0,"",$G18/VLOOKUP($H18,'FX Rates'!$A$1:$BQ$152,_xlfn.XMATCH($B18,'FX Rates'!$A$1:$BQ$1,-1,1),0))))
I19: =IF(ISBLANK($D19),"",_xlfn.XLOOKUP($D19,Item_List,Time_Span,"",0)) | J19: =IF(ISBLANK($H19),"",IF(VLOOKUP($H19,'FX Rates'!$A$1:$BQ$152,_xlfn.XMATCH($B19,'FX Rates'!$A$1:$BQ$1,-1,1),0)=0,"No Exch Rate Data",IF($G19=0,"",$G19/VLOOKUP($H19,'FX Rates'!$A$1:$BQ$152,_xlfn.XMATCH($B19,'FX Rates'!$A$1:$BQ$1,-1,1),0))))
I20: =IF(ISBLANK($D20),"",_xlfn.XLOOKUP($D20,Item_List,Time_Span,"",0)) | J20: =IF(ISBLANK($H20),"",IF(VLOOKUP($H20,'FX Rates'!$A$1:$BQ$152,_xlfn.XMATCH($B20,'FX Rates'!$A$1:$BQ$1,-1,1),0)=0,"No Exch Rate Data",IF($G20=0,"",$G20/VLOOKUP($H20,'FX Rates'!$A$1:$BQ$152,_xlfn.XMATCH($B20,'FX Rates'!$A$1:$BQ$1,-1,1),0))))
... I1000: =IF(ISBLANK($D1000),"",_xlfn.XLOOKUP($D1000,Item_List,Time_Span,"",0)) | J1000: =IF(ISBLANK($H1000),"",IF(VLOOKUP($H1000,'FX Rates'!$A$1:$BQ$152,_xlfn.XMATCH($B1000,'FX Rates'!$A$1:$BQ$1,-1,1),0)=0,"No Exch Rate Data",IF($G1000=0,"",$G1000/VLOOKUP($H1000,'FX Rates'!$A$1:$BQ$152,_xlfn.XMATCH($B1000,'FX Rates'!$A$1:$BQ$1,-1,1),0))))

Sheet Summary
B2: ICSC ELECTRONIC DIARY: Summary of Expenses
C3: Select Summary View Option from Dropdown | D3: =_xlfn.XLOOKUP(SummaryView,Summary_View_List,Summary_View_Explainer) -> Values displayed are the total of all expenses entered in the Data Table
C4: All Expenditures (USD)
C6: ="Exchange rate conversions are based on history of UN Treasury rates from Jan 2021 through "&_xlfn.XLOOKUP(MONTH(MAX('FX Rates'!$1:$1)),Month_Number,Month_List)& " "&YEAR(MAX('FX Rates'!$1:$1)) -> Exchange rate conversions are based on history of UN Treasury rates from Jan 2021 through Aug 2026 | D6: =IF(RIGHT(SummaryView,16)="(Local Currency)",LEFT(SummaryView,LEN(SummaryView)-16)&"("&(_xlfn.XLOOKUP(DSCountry,DS_Country_List,DS_Currency_List))&")",SummaryView) -> All Expenditures (USD)
D7: Category | F7: Total Expense | G7: As Percentage
C8: =IF((RIGHT(SummaryView,5))="(USD)","Expenditures from Last 30 Days (USD)","Expenditures from Last 30 Days ("&(_xlfn.XLOOKUP(DSCountry,DS_Country_List,DS_Currency_List))&")") -> Expenditures from Last 30 Days (USD) | D8: Food and Non Alcoholic Beverages | F8: =VLOOKUP($D8,SummaryTableToggleTable,_xlfn.XMATCH(SummaryView,Summary_View_List,0)+1,FALSE) -> 141.14326 | G8: =IF($F8=0,0,$F8/$F$22) -> 1
C9: =IF((RIGHT(SummaryView,5))="(USD)",SUMIF('Data Table'!B:B,"<="&TODAY(),'Data Table'!J:J)-SUMIF('Data Table'!B:B,"<="&(TODAY()-30),'Data Table'!J:J),(SUMIF('Data Table'!B:B,"<="&TODAY(),'Data Table'!J:J)-SUMIF('Data Table'!B:B,"<="&(TODAY()-30),'Data Table'!J:J))*(VLOOKUP((_xlfn.XLOOKUP(DSCountry,DS_Country_List,DS_Currency_List)),'FX Rates'!$A$1:$BQ$152,2))) -> 141.14326 | D9: Alcohol and Tobacco | F9: =VLOOKUP($D9,SummaryTableToggleTable,_xlfn.XMATCH(SummaryView,Summary_View_List,0)+1,FALSE) -> 0 | G9: =IF($F9=0,0,$F9/$F$22) -> 0
D10: Clothing and Footwear | F10: =VLOOKUP($D10,SummaryTableToggleTable,_xlfn.XMATCH(SummaryView,Summary_View_List,0)+1,FALSE) -> 0 | G10: =IF($F10=0,0,$F10/$F$22) -> 0
D11: Housing | F11: =VLOOKUP($D11,SummaryTableToggleTable,_xlfn.XMATCH(SummaryView,Summary_View_List,0)+1,FALSE) -> 0 | G11: =IF($F11=0,0,$F11/$F$22) -> 0
D12: Furniture Household and Routine Home Maintenance | F12: =VLOOKUP($D12,SummaryTableToggleTable,_xlfn.XMATCH(SummaryView,Summary_View_List,0)+1,FALSE) -> 0 | G12: =IF($F12=0,0,$F12/$F$22) -> 0
C13: =IF((RIGHT(SummaryView,5))="(USD)","Sum of All Expenditures (USD)","Sum of All Expenditures ("&(_xlfn.XLOOKUP(DSCountry,DS_Country_List,DS_Currency_List))&")") -> Sum of All Expenditures (USD) | D13: Health Out of Pocket | F13: =VLOOKUP($D13,SummaryTableToggleTable,_xlfn.XMATCH(SummaryView,Summary_View_List,0)+1,FALSE) -> 0 | G13: =IF($F13=0,0,$F13/$F$22) -> 0
C14: =IF((RIGHT(SummaryView,5))="(USD)",SUM('Data Table'!J:J),SUM('Data Table'!J:J)*(VLOOKUP((_xlfn.XLOOKUP(DSCountry,DS_Country_List,DS_Currency_List)),'FX Rates'!$A$1:$BQ$152,2))) -> 141.14326 | D14: Transport | F14: =VLOOKUP($D14,SummaryTableToggleTable,_xlfn.XMATCH(SummaryView,Summary_View_List,0)+1,FALSE) -> 0 | G14: =IF($F14=0,0,$F14/$F$22) -> 0
D15: Information and Communication | F15: =VLOOKUP($D15,SummaryTableToggleTable,_xlfn.XMATCH(SummaryView,Summary_View_List,0)+1,FALSE) -> 0 | G15: =IF($F15=0,0,$F15/$F$22) -> 0
D16: Recreation and Culture | F16: =VLOOKUP($D16,SummaryTableToggleTable,_xlfn.XMATCH(SummaryView,Summary_View_List,0)+1,FALSE) -> 0 | G16: =IF($F16=0,0,$F16/$F$22) -> 0
D17: Education | F17: =VLOOKUP($D17,SummaryTableToggleTable,_xlfn.XMATCH(SummaryView,Summary_View_List,0)+1,FALSE) -> 0 | G17: =IF($F17=0,0,$F17/$F$22) -> 0
C18: =IF((RIGHT(SummaryView,5))="(USD)","Estimated Monthly Expenditures (USD)","Estimated Monthly Expenditures ("&(_xlfn.XLOOKUP(DSCountry,DS_Country_List,DS_Currency_List))&")") -> Estimated Monthly Expenditures (USD) | D18: Restaurants and Accommodation Services | F18: =VLOOKUP($D18,SummaryTableToggleTable,_xlfn.XMATCH(SummaryView,Summary_View_List,0)+1,FALSE) -> 0 | G18: =IF($F18=0,0,$F18/$F$22) -> 0
C19: =IF((RIGHT(SummaryView,5))="(USD)",SUMIFS('Data Table'!J:J,'Data Table'!B:B,"<="&TODAY(),'Data Table'!I:I,"M")-SUMIFS('Data Table'!J:J,'Data Table'!B:B,"<="&(TODAY()-30),'Data Table'!I:I,"M")+(SUMIFS('Data Table'!J:J,'Data Table'!B:B,"<="&TODAY(),'Data Table'!I:I,"Y")/12)-(SUMIFS('Data Table'!J:J,'Data Table'!B:B,"<="&(TODAY()-360),'Data Table'!I:I,"Y")/12)+(SUMIFS('Data Table'!J:J,'Data Table'!B:B,"<="&TODAY(),'Data Table'!I:I,"5Y")/60-SUMIFS('Data Table'!J:J,'Data Table'!B:B,"<="&(TODAY()-1826),'Data Table'!I:I,"5Y")/60),'Summary Table Toggle'!$H$18) -> 141.14326 | D19: Insurance and Financial Services | F19: =VLOOKUP($D19,SummaryTableToggleTable,_xlfn.XMATCH(SummaryView,Summary_View_List,0)+1,FALSE) -> 0 | G19: =IF($F19=0,0,$F19/$F$22) -> 0
D20: Personal and Miscellaneous Goods and Services | F20: =VLOOKUP($D20,SummaryTableToggleTable,_xlfn.XMATCH(SummaryView,Summary_View_List,0)+1,FALSE) -> 0 | G20: =IF($F20=0,0,$F20/$F$22) -> 0
D21: Other | F21: =VLOOKUP($D21,SummaryTableToggleTable,_xlfn.XMATCH(SummaryView,Summary_View_List,0)+1,FALSE) -> 0 | G21: =IF($F21=0,0,$F21/$F$22) -> 0
D22: TOTAL | F22: =VLOOKUP($D22,SummaryTableToggleTable,_xlfn.XMATCH(SummaryView,Summary_View_List,0)+1,FALSE) -> 141.14326 | G22: =SUM(G8:G21) -> 1

Sheet Monthly Expenses
D2: ICSC Electronic Diary for Monthly Expenditures | E2: INSIDE COUNTRY OF DUTY STATION | H2: OUTSIDE COUNTRY OF DUTY STATION
E3: =IF(ISBLANK(DSCountry),"Specify country in Data Table","Amount Spent in Local Currency ("&(_xlfn.XLOOKUP(DSCountry,DS_Country_List,DS_Currency_List))&")") -> Amount Spent in Local Currency (AUD) | F3: Amount Spent in Other Currency (Expressed in USD) | H3: Amount Spent (Expressed in USD)
C4: Food and Non-Alcoholic Beverages
C5: 1 | D5: Food purchased in supermarkets, stores, markets | E5: =SUMIFS('Data Table'!$G$8:$G$1000,'Data Table'!$D$8:$D$1000,_xlfn.XLOOKUP($C5,Item_List_Number,Item_List,"",0),'Data Table'!$F$8:$F$1000,"Inside",'Data Table'!$H$8:$H$1000,_xlfn.XLOOKUP(DSCountry,DS_Country_List,DS_Currency_List)) -> 200 | F5: =SUMIFS('Data Table'!$J$8:$J$1000,'Data Table'!$D$8:$D$1000,_xlfn.XLOOKUP($C5,Item_List_Number,Item_List,"",0),'Data Table'!$F$8:$F$1000,"Inside",'Data Table'!$H$8:$H$1000,"<>"&_xlfn.XLOOKUP(DSCountry,DS_Country_List,DS_Currency_List)) -> 0 | G5: USD | H5: =SUMIFS('Data Table'!$J$8:$J$1000,'Data Table'!$D$8:$D$1000,_xlfn.XLOOKUP($C5,Item_List_Number,Item_List,"",0),'Data Table'!$F$8:$F$1000,"Outside") -> 0 | I5: USD
C6: 2 | D6: Non-alcoholic beverages | E6: =SUMIFS('Data Table'!$G$8:$G$1000,'Data Table'!$D$8:$D$1000,'Monthly Expenses'!$J6,'Data Table'!$F$8:$F$1000,"Inside",'Data Table'!$H$8:$H$1000,_xlfn.XLOOKUP(DSCountry,DS_Country_List,DS_Currency_List)) -> 0 | F6: =SUMIFS('Data Table'!$J$8:$J$1000,'Data Table'!$D$8:$D$1000,'Monthly Expenses'!$J6,'Data Table'!$F$8:$F$1000,"Inside",'Data Table'!$H$8:$H$1000,"<>"&_xlfn.XLOOKUP(DSCountry,DS_Country_List,DS_Currency_List)) -> 0 | G6: USD | H6: =SUMIFS('Data Table'!$J$8:$J$1000,'Data Table'!$D$8:$D$1000,'Monthly Expenses'!$J6,'Data Table'!$F$8:$F$1000,"Outside") -> 0 | I6: USD
C7: Alcohol and Tobacco
C8: 3 | D8: Alcoholic beverages | E8: =SUMIFS('Data Table'!$G$8:$G$1000,'Data Table'!$D$8:$D$1000,_xlfn.XLOOKUP($C8,Item_List_Number,Item_List,"",0),'Data Table'!$F$8:$F$1000,"Inside",'Data Table'!$H$8:$H$1000,_xlfn.XLOOKUP(DSCountry,DS_Country_List,DS_Currency_List)) -> 0 | F8: =SUMIFS('Data Table'!$J$8:$J$1000,'Data Table'!$D$8:$D$1000,_xlfn.XLOOKUP($C8,Item_List_Number,Item_List,"",0),'Data Table'!$F$8:$F$1000,"Inside",'Data Table'!$H$8:$H$1000,"<>"&_xlfn.XLOOKUP(DSCountry,DS_Country_List,DS_Currency_List)) -> 0 | G8: USD | H8: =SUMIFS('Data Table'!$J$8:$J$1000,'Data Table'!$D$8:$D$1000,_xlfn.XLOOKUP($C8,Item_List_Number,Item_List,"",0),'Data Table'!$F$8:$F$1000,"Outside") -> 0 | I8: USD
C9: 4 | D9: Tobacco and tobacco products | E9: =SUMIFS('Data Table'!$G$8:$G$1000,'Data Table'!$D$8:$D$1000,_xlfn.XLOOKUP($C9,Item_List_Number,Item_List,"",0),'Data Table'!$F$8:$F$1000,"Inside",'Data Table'!$H$8:$H$1000,_xlfn.XLOOKUP(DSCountry,DS_Country_List,DS_Currency_List)) -> 0 | F9: =SUMIFS('Data Table'!$J$8:$J$1000,'Data Table'!$D$8:$D$1000,_xlfn.XLOOKUP($C9,Item_List_Number,Item_List,"",0),'Data Table'!$F$8:$F$1000,"Inside",'Data Table'!$H$8:$H$1000,"<>"&_xlfn.XLOOKUP(DSCountry,DS_Country_List,DS_Currency_List)) -> 0 | G9: USD | H9: =SUMIFS('Data Table'!$J$8:$J$1000,'Data Table'!$D$8:$D$1000,_xlfn.XLOOKUP($C9,Item_List_Number,Item_List,"",0),'Data Table'!$F$8:$F$1000,"Outside") -> 0 | I9: USD
C10: Clothing and Footwear
C11: 5 | D11: Cleaning, repair and tailoring of clothing | E11: =SUMIFS('Data Table'!$G$8:$G$1000,'Data Table'!$D$8:$D$1000,_xlfn.XLOOKUP($C11,Item_List_Number,Item_List,"",0),'Data Table'!$F$8:$F$1000,"Inside",'Data Table'!$H$8:$H$1000,_xlfn.XLOOKUP(DSCountry,DS_Country_List,DS_Currency_List)) -> 0 | F11: =SUMIFS('Data Table'!$J$8:$J$1000,'Data Table'!$D$8:$D$1000,_xlfn.XLOOKUP($C11,Item_List_Number,Item_List,"",0),'Data Table'!$F$8:$F$1000,"Inside",'Data Table'!$H$8:$H$1000,"<>"&_xlfn.XLOOKUP(DSCountry,DS_Country_List,DS_Currency_List)) -> 0 | G11: USD | H11: =SUMIFS('Data Table'!$J$8:$J$1000,'Data Table'!$D$8:$D$1000,_xlfn.XLOOKUP($C11,Item_List_Number,Item_List,"",0),'Data Table'!$F$8:$F$1000,"Outside") -> 0 | I11: USD
C12: Furniture, Household Equipment and Home Maintenance
C13: 6 | D13: Non-durable household goods | E13: =SUMIFS('Data Table'!$G$8:$G$1000,'Data Table'!$D$8:$D$1000,_xlfn.XLOOKUP($C13,Item_List_Number,Item_List,"",0),'Data Table'!$F$8:$F$1000,"Inside",'Data Table'!$H$8:$H$1000,_xlfn.XLOOKUP(DSCountry,DS_Country_List,DS_Currency_List)) -> 0 | F13: =SUMIFS('Data Table'!$J$8:$J$1000,'Data Table'!$D$8:$D$1000,_xlfn.XLOOKUP($C13,Item_List_Number,Item_List,"",0),'Data Table'!$F$8:$F$1000,"Inside",'Data Table'!$H$8:$H$1000,"<>"&_xlfn.XLOOKUP(DSCountry,DS_Country_List,DS_Currency_List)) -> 0 | G13: USD | H13: =SUMIFS('Data Table'!$J$8:$J$1000,'Data Table'!$D$8:$D$1000,_xlfn.XLOOKUP($C13,Item_List_Number,Item_List,"",0),'Data Table'!$F$8:$F$1000,"Outside") -> 0 | I13: USD
C14: Health (Not Covered by Insurance, Out-of-Pocket)
C15: 7 | D15: Medicine | E15: =SUMIFS('Data Table'!$G$8:$G$1000,'Data Table'!$D$8:$D$1000,_xlfn.XLOOKUP($C15,Item_List_Number,Item_List,"",0),'Data Table'!$F$8:$F$1000,"Inside",'Data Table'!$H$8:$H$1000,_xlfn.XLOOKUP(DSCountry,DS_Country_List,DS_Currency_List)) -> 0 | F15: =SUMIFS('Data Table'!$J$8:$J$1000,'Data Table'!$D$8:$D$1000,_xlfn.XLOOKUP($C15,Item_List_Number,Item_List,"",0),'Data Table'!$F$8:$F$1000,"Inside",'Data Table'!$H$8:$H$1000,"<>"&_xlfn.XLOOKUP(DSCountry,DS_Country_List,DS_Currency_List)) -> 0 | G15: USD | H15: =SUMIFS('Data Table'!$J$8:$J$1000,'Data Table'!$D$8:$D$1000,_xlfn.XLOOKUP($C15,Item_List_Number,Item_List,"",0),'Data Table'!$F$8:$F$1000,"Outside") -> 0 | I15: USD
C16: Transport Purchases
C17: 8 | D17: Fuels and lubricants for personal transport | E17: =SUMIFS('Data Table'!$G$8:$G$1000,'Data Table'!$D$8:$D$1000,_xlfn.XLOOKUP($C17,Item_List_Number,Item_List,"",0),'Data Table'!$F$8:$F$1000,"Inside",'Data Table'!$H$8:$H$1000,_xlfn.XLOOKUP(DSCountry,DS_Country_List,DS_Currency_List)) -> 0 | F17: =SUMIFS('Data Table'!$J$8:$J$1000,'Data Table'!$D$8:$D$1000,_xlfn.XLOOKUP($C17,Item_List_Number,Item_List,"",0),'Data Table'!$F$8:$F$1000,"Inside",'Data Table'!$H$8:$H$1000,"<>"&_xlfn.XLOOKUP(DSCountry,DS_Country_List,DS_Currency_List)) -> 0 | G17: USD | H17: =SUMIFS('Data Table'!$J$8:$J$1000,'Data Table'!$D$8:$D$1000,_xlfn.XLOOKUP($C17,Item_List_Number,Item_List,"",0),'Data Table'!$F$8:$F$1000,"Outside") -> 0 | I17: USD
C18: 9 | D18: Public transport and taxi services | E18: =SUMIFS('Data Table'!$G$8:$G$1000,'Data Table'!$D$8:$D$1000,_xlfn.XLOOKUP($C18,Item_List_Number,Item_List,"",0),'Data Table'!$F$8:$F$1000,"Inside",'Data Table'!$H$8:$H$1000,_xlfn.XLOOKUP(DSCountry,DS_Country_List,DS_Currency_List)) -> 0 | F18: =SUMIFS('Data Table'!$J$8:$J$1000,'Data Table'!$D$8:$D$1000,_xlfn.XLOOKUP($C18,Item_List_Number,Item_List,"",0),'Data Table'!$F$8:$F$1000,"Inside",'Data Table'!$H$8:$H$1000,"<>"&_xlfn.XLOOKUP(DSCountry,DS_Country_List,DS_Currency_List)) -> 0 | G18: USD | H18: =SUMIFS('Data Table'!$J$8:$J$1000,'Data Table'!$D$8:$D$1000,_xlfn.XLOOKUP($C18,Item_List_Number,Item_List,"",0),'Data Table'!$F$8:$F$1000,"Outside") -> 0 | I18: USD
C19: 10 | D19: Postal and courier services | E19: =SUMIFS('Data Table'!$G$8:$G$1000,'Data Table'!$D$8:$D$1000,_xlfn.XLOOKUP($C19,Item_List_Number,Item_List,"",0),'Data Table'!$F$8:$F$1000,"Inside",'Data Table'!$H$8:$H$1000,_xlfn.XLOOKUP(DSCountry,DS_Country_List,DS_Currency_List)) -> 0 | F19: =SUMIFS('Data Table'!$J$8:$J$1000,'Data Table'!$D$8:$D$1000,_xlfn.XLOOKUP($C19,Item_List_Number,Item_List,"",0),'Data Table'!$F$8:$F$1000,"Inside",'Data Table'!$H$8:$H$1000,"<>"&_xlfn.XLOOKUP(DSCountry,DS_Country_List,DS_Currency_List)) -> 0 | G19: USD | H19: =SUMIFS('Data Table'!$J$8:$J$1000,'Data Table'!$D$8:$D$1000,_xlfn.XLOOKUP($C19,Item_List_Number,Item_List,"",0),'Data Table'!$F$8:$F$1000,"Outside") -> 0 | I19: USD
C20: 11 | D20: Other transport of goods (removal and storage services, delivery, etc) | E20: =SUMIFS('Data Table'!$G$8:$G$1000,'Data Table'!$D$8:$D$1000,_xlfn.XLOOKUP($C20,Item_List_Number,Item_List,"",0),'Data Table'!$F$8:$F$1000,"Inside",'Data Table'!$H$8:$H$1000,_xlfn.XLOOKUP(DSCountry,DS_Country_List,DS_Currency_List)) -> 0 | F20: =SUMIFS('Data Table'!$J$8:$J$1000,'Data Table'!$D$8:$D$1000,_xlfn.XLOOKUP($C20,Item_List_Number,Item_List,"",0),'Data Table'!$F$8:$F$1000,"Inside",'Data Table'!$H$8:$H$1000,"<>"&_xlfn.XLOOKUP(DSCountry,DS_Country_List,DS_Currency_List)) -> 0 | G20: USD | H20: =SUMIFS('Data Table'!$J$8:$J$1000,'Data Table'!$D$8:$D$1000,_xlfn.XLOOKUP($C20,Item_List_Number,Item_List,"",0),'Data Table'!$F$8:$F$1000,"Outside") -> 0 | I20: USD
C21: Information and Communication
C22: 12 | D22: Information and communication services | E22: =SUMIFS('Data Table'!$G$8:$G$1000,'Data Table'!$D$8:$D$1000,_xlfn.XLOOKUP($C22,Item_List_Number,Item_List,"",0),'Data Table'!$F$8:$F$1000,"Inside",'Data Table'!$H$8:$H$1000,_xlfn.XLOOKUP(DSCountry,DS_Country_List,DS_Currency_List)) -> 0 | F22: =SUMIFS('Data Table'!$J$8:$J$1000,'Data Table'!$D$8:$D$1000,_xlfn.XLOOKUP($C22,Item_List_Number,Item_List,"",0),'Data Table'!$F$8:$F$1000,"Inside",'Data Table'!$H$8:$H$1000,"<>"&_xlfn.XLOOKUP(DSCountry,DS_Country_List,DS_Currency_List)) -> 0 | G22: USD | H22: =SUMIFS('Data Table'!$J$8:$J$1000,'Data Table'!$D$8:$D$1000,_xlfn.XLOOKUP($C22,Item_List_Number,Item_List,"",0),'Data Table'!$F$8:$F$1000,"Outside") -> 0 | I22: USD
C23: Recreation, Sport and Culture
C24: 13 | D24: Pets and pet products | E24: =SUMIFS('Data Table'!$G$8:$G$1000,'Data Table'!$D$8:$D$1000,_xlfn.XLOOKUP($C24,Item_List_Number,Item_List,"",0),'Data Table'!$F$8:$F$1000,"Inside",'Data Table'!$H$8:$H$1000,_xlfn.XLOOKUP(DSCountry,DS_Country_List,DS_Currency_List)) -> 0 | F24: =SUMIFS('Data Table'!$J$8:$J$1000,'Data Table'!$D$8:$D$1000,_xlfn.XLOOKUP($C24,Item_List_Number,Item_List,"",0),'Data Table'!$F$8:$F$1000,"Inside",'Data Table'!$H$8:$H$1000,"<>"&_xlfn.XLOOKUP(DSCountry,DS_Country_List,DS_Currency_List)) -> 0 | G24: USD | H24: =SUMIFS('Data Table'!$J$8:$J$1000,'Data Table'!$D$8:$D$1000,_xlfn.XLOOKUP($C24,Item_List_Number,Item_List,"",0),'Data Table'!$F$8:$F$1000,"Outside") -> 0 | I24: USD
C25: 14 | D25: Veterinary and other services for pets | E25: =SUMIFS('Data Table'!$G$8:$G$1000,'Data Table'!$D$8:$D$1000,_xlfn.XLOOKUP($C25,Item_List_Number,Item_List,"",0),'Data Table'!$F$8:$F$1000,"Inside",'Data Table'!$H$8:$H$1000,_xlfn.XLOOKUP(DSCountry,DS_Country_List,DS_Currency_List)) -> 0 | F25: =SUMIFS('Data Table'!$J$8:$J$1000,'Data Table'!$D$8:$D$1000,_xlfn.XLOOKUP($C25,Item_List_Number,Item_List,"",0),'Data Table'!$F$8:$F$1000,"Inside",'Data Table'!$H$8:$H$1000,"<>"&_xlfn.XLOOKUP(DSCountry,DS_Country_List,DS_Currency_List)) -> 0 | G25: USD | H25: =SUMIFS('Data Table'!$J$8:$J$1000,'Data Table'!$D$8:$D$1000,_xlfn.XLOOKUP($C25,Item_List_Number,Item_List,"",0),'Data Table'!$F$8:$F$1000,"Outside") -> 0 | I25: USD
C26: 15 | D26: Cultural services | E26: =SUMIFS('Data Table'!$G$8:$G$1000,'Data Table'!$D$8:$D$1000,_xlfn.XLOOKUP($C26,Item_List_Number,Item_List,"",0),'Data Table'!$F$8:$F$1000,"Inside",'Data Table'!$H$8:$H$1000,_xlfn.XLOOKUP(DSCountry,DS_Country_List,DS_Currency_List)) -> 0 | F26: =SUMIFS('Data Table'!$J$8:$J$1000,'Data Table'!$D$8:$D$1000,_xlfn.XLOOKUP($C26,Item_List_Number,Item_List,"",0),'Data Table'!$F$8:$F$1000,"Inside",'Data Table'!$H$8:$H$1000,"<>"&_xlfn.XLOOKUP(DSCountry,DS_Country_List,DS_Currency_List)) -> 0 | G26: USD | H26: =SUMIFS('Data Table'!$J$8:$J$1000,'Data Table'!$D$8:$D$1000,_xlfn.XLOOKUP($C26,Item_List_Number,Item_List,"",0),'Data Table'!$F$8:$F$1000,"Outside") -> 0 | I26: USD
C27: 16 | D27: Recreational and sporting services | E27: =SUMIFS('Data Table'!$G$8:$G$1000,'Data Table'!$D$8:$D$1000,_xlfn.XLOOKUP($C27,Item_List_Number,Item_List,"",0),'Data Table'!$F$8:$F$1000,"Inside",'Data Table'!$H$8:$H$1000,_xlfn.XLOOKUP(DSCountry,DS_Country_List,DS_Currency_List)) -> 0 | F27: =SUMIFS('Data Table'!$J$8:$J$1000,'Data Table'!$D$8:$D$1000,_xlfn.XLOOKUP($C27,Item_List_Number,Item_List,"",0),'Data Table'!$F$8:$F$1000,"Inside",'Data Table'!$H$8:$H$1000,"<>"&_xlfn.XLOOKUP(DSCountry,DS_Country_List,DS_Currency_List)) -> 0 | G27: USD | H27: =SUMIFS('Data Table'!$J$8:$J$1000,'Data Table'!$D$8:$D$1000,_xlfn.XLOOKUP($C27,Item_List_Number,Item_List,"",0),'Data Table'!$F$8:$F$1000,"Outside") -> 0 | I27: USD
C28: 17 | D28: Newspapers, books and stationery | E28: =SUMIFS('Data Table'!$G$8:$G$1000,'Data Table'!$D$8:$D$1000,_xlfn.XLOOKUP($C28,Item_List_Number,Item_List,"",0),'Data Table'!$F$8:$F$1000,"Inside",'Data Table'!$H$8:$H$1000,_xlfn.XLOOKUP(DSCountry,DS_Country_List,DS_Currency_List)) -> 0 | F28: =SUMIFS('Data Table'!$J$8:$J$1000,'Data Table'!$D$8:$D$1000,_xlfn.XLOOKUP($C28,Item_List_Number,Item_List,"",0),'Data Table'!$F$8:$F$1000,"Inside",'Data Table'!$H$8:$H$1000,"<>"&_xlfn.XLOOKUP(DSCountry,DS_Country_List,DS_Currency_List)) -> 0 | G28: USD | H28: =SUMIFS('Data Table'!$J$8:$J$1000,'Data Table'!$D$8:$D$1000,_xlfn.XLOOKUP($C28,Item_List_Number,Item_List,"",0),'Data Table'!$F$8:$F$1000,"Outside") -> 0 | I28: USD
C29: Restaurants and Accommodation Services
C30: 18 | D30: Restaurants, cafes and similar eating facilities | E30: =SUMIFS('Data Table'!$G$8:$G$1000,'Data Table'!$D$8:$D$1000,_xlfn.XLOOKUP($C30,Item_List_Number,Item_List,"",0),'Data Table'!$F$8:$F$1000,"Inside",'Data Table'!$H$8:$H$1000,_xlfn.XLOOKUP(DSCountry,DS_Country_List,DS_Currency_List)) -> 0 | F30: =SUMIFS('Data Table'!$J$8:$J$1000,'Data Table'!$D$8:$D$1000,_xlfn.XLOOKUP($C30,Item_List_Number,Item_List,"",0),'Data Table'!$F$8:$F$1000,"Inside",'Data Table'!$H$8:$H$1000,"<>"&_xlfn.XLOOKUP(DSCountry,DS_Country_List,DS_Currency_List)) -> 0 | G30: USD | H30: =SUMIFS('Data Table'!$J$8:$J$1000,'Data Table'!$D$8:$D$1000,_xlfn.XLOOKUP($C30,Item_List_Number,Item_List,"",0),'Data Table'!$F$8:$F$1000,"Outside") -> 0 | I30: USD
C31: 19 | D31: Canteens, cafeterias and refectories | E31: =SUMIFS('Data Table'!$G$8:$G$1000,'Data Table'!$D$8:$D$1000,_xlfn.XLOOKUP($C31,Item_List_Number,Item_List,"",0),'Data Table'!$F$8:$F$1000,"Inside",'Data Table'!$H$8:$H$1000,_xlfn.XLOOKUP(DSCountry,DS_Country_List,DS_Currency_List)) -> 0 | F31: =SUMIFS('Data Table'!$J$8:$J$1000,'Data Table'!$D$8:$D$1000,_xlfn.XLOOKUP($C31,Item_List_Number,Item_List,"",0),'Data Table'!$F$8:$F$1000,"Inside",'Data Table'!$H$8:$H$1000,"<>"&_xlfn.XLOOKUP(DSCountry,DS_Country_List,DS_Currency_List)) -> 0 | G31: USD | H31: =SUMIFS('Data Table'!$J$8:$J$1000,'Data Table'!$D$8:$D$1000,_xlfn.XLOOKUP($C31,Item_List_Number,Item_List,"",0),'Data Table'!$F$8:$F$1000,"Outside") -> 0 | I31: USD
C32: Insurance and Financial Services
C33: 20 | D33: Insurance connected with health (supplementary medical insurance) | E33: =SUMIFS('Data Table'!$G$8:$G$1000,'Data Table'!$D$8:$D$1000,_xlfn.XLOOKUP($C33,Item_List_Number,Item_List,"",0),'Data Table'!$F$8:$F$1000,"Inside",'Data Table'!$H$8:$H$1000,_xlfn.XLOOKUP(DSCountry,DS_Country_List,DS_Currency_List)) -> 0 | F33: =SUMIFS('Data Table'!$J$8:$J$1000,'Data Table'!$D$8:$D$1000,_xlfn.XLOOKUP($C33,Item_List_Number,Item_List,"",0),'Data Table'!$F$8:$F$1000,"Inside",'Data Table'!$H$8:$H$1000,"<>"&_xlfn.XLOOKUP(DSCountry,DS_Country_List,DS_Currency_List)) -> 0 | G33: USD | H33: =SUMIFS('Data Table'!$J$8:$J$1000,'Data Table'!$D$8:$D$1000,_xlfn.XLOOKUP($C33,Item_List_Number,Item_List,"",0),'Data Table'!$F$8:$F$1000,"Outside") -> 0 | I33: USD
C34: 21 | D34: Insurance connected with transport | E34: =SUMIFS('Data Table'!$G$8:$G$1000,'Data Table'!$D$8:$D$1000,_xlfn.XLOOKUP($C34,Item_List_Number,Item_List,"",0),'Data Table'!$F$8:$F$1000,"Inside",'Data Table'!$H$8:$H$1000,_xlfn.XLOOKUP(DSCountry,DS_Country_List,DS_Currency_List)) -> 0 | F34: =SUMIFS('Data Table'!$J$8:$J$1000,'Data Table'!$D$8:$D$1000,_xlfn.XLOOKUP($C34,Item_List_Number,Item_List,"",0),'Data Table'!$F$8:$F$1000,"Inside",'Data Table'!$H$8:$H$1000,"<>"&_xlfn.XLOOKUP(DSCountry,DS_Country_List,DS_Currency_List)) -> 0 | G34: USD | H34: =SUMIFS('Data Table'!$J$8:$J$1000,'Data Table'!$D$8:$D$1000,_xlfn.XLOOKUP($C34,Item_List_Number,Item_List,"",0),'Data Table'!$F$8:$F$1000,"Outside") -> 0 | I34: USD
C35: 22 | D35: Insurance connected with dwelling | E35: =SUMIFS('Data Table'!$G$8:$G$1000,'Data Table'!$D$8:$D$1000,_xlfn.XLOOKUP($C35,Item_List_Number,Item_List,"",0),'Data Table'!$F$8:$F$1000,"Inside",'Data Table'!$H$8:$H$1000,_xlfn.XLOOKUP(DSCountry,DS_Country_List,DS_Currency_List)) -> 0 | F35: =SUMIFS('Data Table'!$J$8:$J$1000,'Data Table'!$D$8:$D$1000,_xlfn.XLOOKUP($C35,Item_List_Number,Item_List,"",0),'Data Table'!$F$8:$F$1000,"Inside",'Data Table'!$H$8:$H$1000,"<>"&_xlfn.XLOOKUP(DSCountry,DS_Country_List,DS_Currency_List)) -> 0 | G35: USD | H35: =SUMIFS('Data Table'!$J$8:$J$1000,'Data Table'!$D$8:$D$1000,_xlfn.XLOOKUP($C35,Item_List_Number,Item_List,"",0),'Data Table'!$F$8:$F$1000,"Outside") -> 0 | I35: USD
C36: Personal Care, Social Protection and Miscellaneous Goods and Services
C37: 23 | D37: Hairdressing salons and personal grooming establishments | E37: =SUMIFS('Data Table'!$G$8:$G$1000,'Data Table'!$D$8:$D$1000,_xlfn.XLOOKUP($C37,Item_List_Number,Item_List,"",0),'Data Table'!$F$8:$F$1000,"Inside",'Data Table'!$H$8:$H$1000,_xlfn.XLOOKUP(DSCountry,DS_Country_List,DS_Currency_List)) -> 0 | F37: =SUMIFS('Data Table'!$J$8:$J$1000,'Data Table'!$D$8:$D$1000,_xlfn.XLOOKUP($C37,Item_List_Number,Item_List,"",0),'Data Table'!$F$8:$F$1000,"Inside",'Data Table'!$H$8:$H$1000,"<>"&_xlfn.XLOOKUP(DSCountry,DS_Country_List,DS_Currency_List)) -> 0 | G37: USD | H37: =SUMIFS('Data Table'!$J$8:$J$1000,'Data Table'!$D$8:$D$1000,_xlfn.XLOOKUP($C37,Item_List_Number,Item_List,"",0),'Data Table'!$F$8:$F$1000,"Outside") -> 0 | I37: USD
C38: Other Expenditures
C39: 24 | D39: Remittances except medical and educational expenses | E39: =SUMIFS('Data Table'!$G$8:$G$1000,'Data Table'!$D$8:$D$1000,_xlfn.XLOOKUP($C39,Item_List_Number,Item_List,"",0),'Data Table'!$F$8:$F$1000,"Inside",'Data Table'!$H$8:$H$1000,_xlfn.XLOOKUP(DSCountry,DS_Country_List,DS_Currency_List)) -> 0 | F39: =SUMIFS('Data Table'!$J$8:$J$1000,'Data Table'!$D$8:$D$1000,_xlfn.XLOOKUP($C39,Item_List_Number,Item_List,"",0),'Data Table'!$F$8:$F$1000,"Inside",'Data Table'!$H$8:$H$1000,"<>"&_xlfn.XLOOKUP(DSCountry,DS_Country_List,DS_Currency_List)) -> 0 | G39: USD | H39: =SUMIFS('Data Table'!$J$8:$J$1000,'Data Table'!$D$8:$D$1000,_xlfn.XLOOKUP($C39,Item_List_Number,Item_List,"",0),'Data Table'!$F$8:$F$1000,"Outside") -> 0 | I39: USD
C40: 25 | D40: Other monthly expenditures | E40: =SUMIFS('Data Table'!$G$8:$G$1000,'Data Table'!$D$8:$D$1000,_xlfn.XLOOKUP($C40,Item_List_Number,Item_List,"",0),'Data Table'!$F$8:$F$1000,"Inside",'Data Table'!$H$8:$H$1000,_xlfn.XLOOKUP(DSCountry,DS_Country_List,DS_Currency_List)) -> 0 | F40: =SUMIFS('Data Table'!$J$8:$J$1000,'Data Table'!$D$8:$D$1000,_xlfn.XLOOKUP($C40,Item_List_Number,Item_List,"",0),'Data Table'!$F$8:$F$1000,"Inside",'Data Table'!$H$8:$H$1000,"<>"&_xlfn.XLOOKUP(DSCountry,DS_Country_List,DS_Currency_List)) -> 0 | G40: USD | H40: =SUMIFS('Data Table'!$J$8:$J$1000,'Data Table'!$D$8:$D$1000,_xlfn.XLOOKUP($C40,Item_List_Number,Item_List,"",0),'Data Table'!$F$8:$F$1000,"Outside") -> 0 | I40: USD
C41: Housing Expenditures and Domestic and Security Services
...

Sheet Yearly and Education Expenses
D2: ICSC Electronic Diary for Yearly Expenditures and Education | E2: INSIDE COUNTRY OF DUTY STATION | H2: OUTSIDE COUNTRY OF DUTY STATION
E3: =IF(ISBLANK(DSCountry),"Specify country in Data Table","Amount Spent in Local Currency ("&(_xlfn.XLOOKUP(DSCountry,DS_Country_List,DS_Currency_List))&")") -> Amount Spent in Local Currency (AUD) | F3: Amount Spent in Other Currency (Expressed in USD) | H3: Amount Spent (Expressed in USD)
C4: Clothing and Footwear
C5: 26 | D5: Clothing garments | E5: =SUMIFS('Data Table'!$G$8:$G$1000,'Data Table'!$D$8:$D$1000,_xlfn.XLOOKUP($C5,Item_List_Number,Item_List,"",0),'Data Table'!$F$8:$F$1000,"Inside",'Data Table'!$H$8:$H$1000,_xlfn.XLOOKUP(DSCountry,DS_Country_List,DS_Currency_List)) -> 0 | F5: =SUMIFS('Data Table'!$J$8:$J$1000,'Data Table'!$D$8:$D$1000,_xlfn.XLOOKUP($C5,Item_List_Number,Item_List,"",0),'Data Table'!$F$8:$F$1000,"Inside",'Data Table'!$H$8:$H$1000,"<>"&_xlfn.XLOOKUP(DSCountry,DS_Country_List,DS_Currency_List)) -> 0 | G5: USD | H5: =SUMIFS('Data Table'!$J$8:$J$1000,'Data Table'!$D$8:$D$1000,_xlfn.XLOOKUP($C5,Item_List_Number,Item_List,"",0),'Data Table'!$F$8:$F$1000,"Outside") -> 0 | I5: USD
C6: 27 | D6: Other articles of clothing and clothing accessories | E6: =SUMIFS('Data Table'!$G$8:$G$1000,'Data Table'!$D$8:$D$1000,_xlfn.XLOOKUP($C6,Item_List_Number,Item_List,"",0),'Data Table'!$F$8:$F$1000,"Inside",'Data Table'!$H$8:$H$1000,_xlfn.XLOOKUP(DSCountry,DS_Country_List,DS_Currency_List)) -> 0 | F6: =SUMIFS('Data Table'!$J$8:$J$1000,'Data Table'!$D$8:$D$1000,_xlfn.XLOOKUP($C6,Item_List_Number,Item_List,"",0),'Data Table'!$F$8:$F$1000,"Inside",'Data Table'!$H$8:$H$1000,"<>"&_xlfn.XLOOKUP(DSCountry,DS_Country_List,DS_Currency_List)) -> 0 | G6: USD | H6: =SUMIFS('Data Table'!$J$8:$J$1000,'Data Table'!$D$8:$D$1000,_xlfn.XLOOKUP($C6,Item_List_Number,Item_List,"",0),'Data Table'!$F$8:$F$1000,"Outside") -> 0 | I6: USD
C7: 28 | D7: Shoes and other footwear | E7: =SUMIFS('Data Table'!$G$8:$G$1000,'Data Table'!$D$8:$D$1000,_xlfn.XLOOKUP($C7,Item_List_Number,Item_List,"",0),'Data Table'!$F$8:$F$1000,"Inside",'Data Table'!$H$8:$H$1000,_xlfn.XLOOKUP(DSCountry,DS_Country_List,DS_Currency_List)) -> 0 | F7: =SUMIFS('Data Table'!$J$8:$J$1000,'Data Table'!$D$8:$D$1000,_xlfn.XLOOKUP($C7,Item_List_Number,Item_List,"",0),'Data Table'!$F$8:$F$1000,"Inside",'Data Table'!$H$8:$H$1000,"<>"&_xlfn.XLOOKUP(DSCountry,DS_Country_List,DS_Currency_List)) -> 0 | G7: USD | H7: =SUMIFS('Data Table'!$J$8:$J$1000,'Data Table'!$D$8:$D$1000,_xlfn.XLOOKUP($C7,Item_List_Number,Item_List,"",0),'Data Table'!$F$8:$F$1000,"Outside") -> 0 | I7: USD
C8: Furniture, Household Equipment, Maintenance
C9: 29 | D9: Furniture, furnishings and loose carpets | E9: =SUMIFS('Data Table'!$G$8:$G$1000,'Data Table'!$D$8:$D$1000,_xlfn.XLOOKUP($C9,Item_List_Number,Item_List,"",0),'Data Table'!$F$8:$F$1000,"Inside",'Data Table'!$H$8:$H$1000,_xlfn.XLOOKUP(DSCountry,DS_Country_List,DS_Currency_List)) -> 0 | F9: =SUMIFS('Data Table'!$J$8:$J$1000,'Data Table'!$D$8:$D$1000,_xlfn.XLOOKUP($C9,Item_List_Number,Item_List,"",0),'Data Table'!$F$8:$F$1000,"Inside",'Data Table'!$H$8:$H$1000,"<>"&_xlfn.XLOOKUP(DSCountry,DS_Country_List,DS_Currency_List)) -> 0 | G9: USD | H9: =SUMIFS('Data Table'!$J$8:$J$1000,'Data Table'!$D$8:$D$1000,_xlfn.XLOOKUP($C9,Item_List_Number,Item_List,"",0),'Data Table'!$F$8:$F$1000,"Outside") -> 0 | I9: USD
C10: 30 | D10: Households textiles | E10: =SUMIFS('Data Table'!$G$8:$G$1000,'Data Table'!$D$8:$D$1000,_xlfn.XLOOKUP($C10,Item_List_Number,Item_List,"",0),'Data Table'!$F$8:$F$1000,"Inside",'Data Table'!$H$8:$H$1000,_xlfn.XLOOKUP(DSCountry,DS_Country_List,DS_Currency_List)) -> 0 | F10: =SUMIFS('Data Table'!$J$8:$J$1000,'Data Table'!$D$8:$D$1000,_xlfn.XLOOKUP($C10,Item_List_Number,Item_List,"",0),'Data Table'!$F$8:$F$1000,"Inside",'Data Table'!$H$8:$H$1000,"<>"&_xlfn.XLOOKUP(DSCountry,DS_Country_List,DS_Currency_List)) -> 0 | G10: USD | H10: =SUMIFS('Data Table'!$J$8:$J$1000,'Data Table'!$D$8:$D$1000,_xlfn.XLOOKUP($C10,Item_List_Number,Item_List,"",0),'Data Table'!$F$8:$F$1000,"Outside") -> 0 | I10: USD
C11: 31 | D11: Small household appliances | E11: =SUMIFS('Data Table'!$G$8:$G$1000,'Data Table'!$D$8:$D$1000,_xlfn.XLOOKUP($C11,Item_List_Number,Item_List,"",0),'Data Table'!$F$8:$F$1000,"Inside",'Data Table'!$H$8:$H$1000,_xlfn.XLOOKUP(DSCountry,DS_Country_List,DS_Currency_List)) -> 0 | F11: =SUMIFS('Data Table'!$J$8:$J$1000,'Data Table'!$D$8:$D$1000,_xlfn.XLOOKUP($C11,Item_List_Number,Item_List,"",0),'Data Table'!$F$8:$F$1000,"Inside",'Data Table'!$H$8:$H$1000,"<>"&_xlfn.XLOOKUP(DSCountry,DS_Country_List,DS_Currency_List)) -> 0 | G11: USD | H11: =SUMIFS('Data Table'!$J$8:$J$1000,'Data Table'!$D$8:$D$1000,_xlfn.XLOOKUP($C11,Item_List_Number,Item_List,"",0),'Data Table'!$F$8:$F$1000,"Outside") -> 0 | I11: USD
C12: 32 | D12: Glassware, tableware and household utensils | E12: =SUMIFS('Data Table'!$G$8:$G$1000,'Data Table'!$D$8:$D$1000,_xlfn.XLOOKUP($C12,Item_List_Number,Item_List,"",0),'Data Table'!$F$8:$F$1000,"Inside",'Data Table'!$H$8:$H$1000,_xlfn.XLOOKUP(DSCountry,DS_Country_List,DS_Currency_List)) -> 0 | F12: =SUMIFS('Data Table'!$J$8:$J$1000,'Data Table'!$D$8:$D$1000,_xlfn.XLOOKUP($C12,Item_List_Number,Item_List,"",0),'Data Table'!$F$8:$F$1000,"Inside",'Data Table'!$H$8:$H$1000,"<>"&_xlfn.XLOOKUP(DSCountry,DS_Country_List,DS_Currency_List)) -> 0 | G12: USD | H12: =SUMIFS('Data Table'!$J$8:$J$1000,'Data Table'!$D$8:$D$1000,_xlfn.XLOOKUP($C12,Item_List_Number,Item_List,"",0),'Data Table'!$F$8:$F$1000,"Outside") -> 0 | I12: USD
C13: 33 | D13: Tools and equipment for house and garden | E13: =SUMIFS('Data Table'!$G$8:$G$1000,'Data Table'!$D$8:$D$1000,_xlfn.XLOOKUP($C13,Item_List_Number,Item_List,"",0),'Data Table'!$F$8:$F$1000,"Inside",'Data Table'!$H$8:$H$1000,_xlfn.XLOOKUP(DSCountry,DS_Country_List,DS_Currency_List)) -> 0 | F13: =SUMIFS('Data Table'!$J$8:$J$1000,'Data Table'!$D$8:$D$1000,_xlfn.XLOOKUP($C13,Item_List_Number,Item_List,"",0),'Data Table'!$F$8:$F$1000,"Inside",'Data Table'!$H$8:$H$1000,"<>"&_xlfn.XLOOKUP(DSCountry,DS_Country_List,DS_Currency_List)) -> 0 | G13: USD | H13: =SUMIFS('Data Table'!$J$8:$J$1000,'Data Table'!$D$8:$D$1000,_xlfn.XLOOKUP($C13,Item_List_Number,Item_List,"",0),'Data Table'!$F$8:$F$1000,"Outside") -> 0 | I13: USD
C14: Health (Not Covered by Insurance, Out-of-Pocket)
C15: 34 | D15: Medical products | E15: =SUMIFS('Data Table'!$G$8:$G$1000,'Data Table'!$D$8:$D$1000,_xlfn.XLOOKUP($C15,Item_List_Number,Item_List,"",0),'Data Table'!$F$8:$F$1000,"Inside",'Data Table'!$H$8:$H$1000,_xlfn.XLOOKUP(DSCountry,DS_Country_List,DS_Currency_List)) -> 0 | F15: =SUMIFS('Data Table'!$J$8:$J$1000,'Data Table'!$D$8:$D$1000,_xlfn.XLOOKUP($C15,Item_List_Number,Item_List,"",0),'Data Table'!$F$8:$F$1000,"Inside",'Data Table'!$H$8:$H$1000,"<>"&_xlfn.XLOOKUP(DSCountry,DS_Country_List,DS_Currency_List)) -> 0 | G15: USD | H15: =SUMIFS('Data Table'!$J$8:$J$1000,'Data Table'!$D$8:$D$1000,_xlfn.XLOOKUP($C15,Item_List_Number,Item_List,"",0),'Data Table'!$F$8:$F$1000,"Outside") -> 0 | I15: USD
C16: 35 | D16: Assistive products | E16: =SUMIFS('Data Table'!$G$8:$G$1000,'Data Table'!$D$8:$D$1000,_xlfn.XLOOKUP($C16,Item_List_Number,Item_List,"",0),'Data Table'!$F$8:$F$1000,"Inside",'Data Table'!$H$8:$H$1000,_xlfn.XLOOKUP(DSCountry,DS_Country_List,DS_Currency_List)) -> 0 | F16: =SUMIFS('Data Table'!$J$8:$J$1000,'Data Table'!$D$8:$D$1000,_xlfn.XLOOKUP($C16,Item_List_Number,Item_List,"",0),'Data Table'!$F$8:$F$1000,"Inside",'Data Table'!$H$8:$H$1000,"<>"&_xlfn.XLOOKUP(DSCountry,DS_Country_List,DS_Currency_List)) -> 0 | G16: USD | H16: =SUMIFS('Data Table'!$J$8:$J$1000,'Data Table'!$D$8:$D$1000,_xlfn.XLOOKUP($C16,Item_List_Number,Item_List,"",0),'Data Table'!$F$8:$F$1000,"Outside") -> 0 | I16: USD
C17: 36 | D17: Outpatient care services | E17: =SUMIFS('Data Table'!$G$8:$G$1000,'Data Table'!$D$8:$D$1000,_xlfn.XLOOKUP($C17,Item_List_Number,Item_List,"",0),'Data Table'!$F$8:$F$1000,"Inside",'Data Table'!$H$8:$H$1000,_xlfn.XLOOKUP(DSCountry,DS_Country_List,DS_Currency_List)) -> 0 | F17: =SUMIFS('Data Table'!$J$8:$J$1000,'Data Table'!$D$8:$D$1000,_xlfn.XLOOKUP($C17,Item_List_Number,Item_List,"",0),'Data Table'!$F$8:$F$1000,"Inside",'Data Table'!$H$8:$H$1000,"<>"&_xlfn.XLOOKUP(DSCountry,DS_Country_List,DS_Currency_List)) -> 0 | G17: USD | H17: =SUMIFS('Data Table'!$J$8:$J$1000,'Data Table'!$D$8:$D$1000,_xlfn.XLOOKUP($C17,Item_List_Number,Item_List,"",0),'Data Table'!$F$8:$F$1000,"Outside") -> 0 | I17: USD
C18: 37 | D18: In-patient care services | E18: =SUMIFS('Data Table'!$G$8:$G$1000,'Data Table'!$D$8:$D$1000,_xlfn.XLOOKUP($C18,Item_List_Number,Item_List,"",0),'Data Table'!$F$8:$F$1000,"Inside",'Data Table'!$H$8:$H$1000,_xlfn.XLOOKUP(DSCountry,DS_Country_List,DS_Currency_List)) -> 0 | F18: =SUMIFS('Data Table'!$J$8:$J$1000,'Data Table'!$D$8:$D$1000,_xlfn.XLOOKUP($C18,Item_List_Number,Item_List,"",0),'Data Table'!$F$8:$F$1000,"Inside",'Data Table'!$H$8:$H$1000,"<>"&_xlfn.XLOOKUP(DSCountry,DS_Country_List,DS_Currency_List)) -> 0 | G18: USD | H18: =SUMIFS('Data Table'!$J$8:$J$1000,'Data Table'!$D$8:$D$1000,_xlfn.XLOOKUP($C18,Item_List_Number,Item_List,"",0),'Data Table'!$F$8:$F$1000,"Outside") -> 0 | I18: USD
C19: Transport Purchases
C20: 38 | D20: Parts and accessories for personal transport equipment | E20: =SUMIFS('Data Table'!$G$8:$G$1000,'Data Table'!$D$8:$D$1000,_xlfn.XLOOKUP($C20,Item_List_Number,Item_List,"",0),'Data Table'!$F$8:$F$1000,"Inside",'Data Table'!$H$8:$H$1000,_xlfn.XLOOKUP(DSCountry,DS_Country_List,DS_Currency_List)) -> 0 | F20: =SUMIFS('Data Table'!$J$8:$J$1000,'Data Table'!$D$8:$D$1000,_xlfn.XLOOKUP($C20,Item_List_Number,Item_List,"",0),'Data Table'!$F$8:$F$1000,"Inside",'Data Table'!$H$8:$H$1000,"<>"&_xlfn.XLOOKUP(DSCountry,DS_Country_List,DS_Currency_List)) -> 0 | G20: USD | H20: =SUMIFS('Data Table'!$J$8:$J$1000,'Data Table'!$D$8:$D$1000,_xlfn.XLOOKUP($C20,Item_List_Number,Item_List,"",0),'Data Table'!$F$8:$F$1000,"Outside") -> 0 | I20: USD
C21: 39 | D21: Maintenance and repair of personal transport equipment | E21: =SUMIFS('Data Table'!$G$8:$G$1000,'Data Table'!$D$8:$D$1000,_xlfn.XLOOKUP($C21,Item_List_Number,Item_List,"",0),'Data Table'!$F$8:$F$1000,"Inside",'Data Table'!$H$8:$H$1000,_xlfn.XLOOKUP(DSCountry,DS_Country_List,DS_Currency_List)) -> 0 | F21: =SUMIFS('Data Table'!$J$8:$J$1000,'Data Table'!$D$8:$D$1000,_xlfn.XLOOKUP($C21,Item_List_Number,Item_List,"",0),'Data Table'!$F$8:$F$1000,"Inside",'Data Table'!$H$8:$H$1000,"<>"&_xlfn.XLOOKUP(DSCountry,DS_Country_List,DS_Currency_List)) -> 0 | G21: USD | H21: =SUMIFS('Data Table'!$J$8:$J$1000,'Data Table'!$D$8:$D$1000,_xlfn.XLOOKUP($C21,Item_List_Number,Item_List,"",0),'Data Table'!$F$8:$F$1000,"Outside") -> 0 | I21: USD
C22: 40 | D22: Other services related to personal transport equipment | E22: =SUMIFS('Data Table'!$G$8:$G$1000,'Data Table'!$D$8:$D$1000,_xlfn.XLOOKUP($C22,Item_List_Number,Item_List,"",0),'Data Table'!$F$8:$F$1000,"Inside",'Data Table'!$H$8:$H$1000,_xlfn.XLOOKUP(DSCountry,DS_Country_List,DS_Currency_List)) -> 0 | F22: =SUMIFS('Data Table'!$J$8:$J$1000,'Data Table'!$D$8:$D$1000,_xlfn.XLOOKUP($C22,Item_List_Number,Item_List,"",0),'Data Table'!$F$8:$F$1000,"Inside",'Data Table'!$H$8:$H$1000,"<>"&_xlfn.XLOOKUP(DSCountry,DS_Country_List,DS_Currency_List)) -> 0 | G22: USD | H22: =SUMIFS('Data Table'!$J$8:$J$1000,'Data Table'!$D$8:$D$1000,_xlfn.XLOOKUP($C22,Item_List_Number,Item_List,"",0),'Data Table'!$F$8:$F$1000,"Outside") -> 0 | I22: USD
C23: 41 | D23: Air Travel | E23: =SUMIFS('Data Table'!$G$8:$G$1000,'Data Table'!$D$8:$D$1000,_xlfn.XLOOKUP($C23,Item_List_Number,Item_List,"",0),'Data Table'!$F$8:$F$1000,"Inside",'Data Table'!$H$8:$H$1000,_xlfn.XLOOKUP(DSCountry,DS_Country_List,DS_Currency_List)) -> 0 | F23: =SUMIFS('Data Table'!$J$8:$J$1000,'Data Table'!$D$8:$D$1000,_xlfn.XLOOKUP($C23,Item_List_Number,Item_List,"",0),'Data Table'!$F$8:$F$1000,"Inside",'Data Table'!$H$8:$H$1000,"<>"&_xlfn.XLOOKUP(DSCountry,DS_Country_List,DS_Currency_List)) -> 0 | G23: USD | H23: =SUMIFS('Data Table'!$J$8:$J$1000,'Data Table'!$D$8:$D$1000,_xlfn.XLOOKUP($C23,Item_List_Number,Item_List,"",0),'Data Table'!$F$8:$F$1000,"Outside") -> 0 | I23: USD
C24: Information and Communication
C25: 42 | D25: Information and communication equipment | E25: =SUMIFS('Data Table'!$G$8:$G$1000,'Data Table'!$D$8:$D$1000,_xlfn.XLOOKUP($C25,Item_List_Number,Item_List,"",0),'Data Table'!$F$8:$F$1000,"Inside",'Data Table'!$H$8:$H$1000,_xlfn.XLOOKUP(DSCountry,DS_Country_List,DS_Currency_List)) -> 0 | F25: =SUMIFS('Data Table'!$J$8:$J$1000,'Data Table'!$D$8:$D$1000,_xlfn.XLOOKUP($C25,Item_List_Number,Item_List,"",0),'Data Table'!$F$8:$F$1000,"Inside",'Data Table'!$H$8:$H$1000,"<>"&_xlfn.XLOOKUP(DSCountry,DS_Country_List,DS_Currency_List)) -> 0 | G25: USD | H25: =SUMIFS('Data Table'!$J$8:$J$1000,'Data Table'!$D$8:$D$1000,_xlfn.XLOOKUP($C25,Item_List_Number,Item_List,"",0),'Data Table'!$F$8:$F$1000,"Outside") -> 0 | I25: USD
C26: Recreation and Culture
C27: 43 | D27: Sport, camping and open-air equipment | E27: =SUMIFS('Data Table'!$G$8:$G$1000,'Data Table'!$D$8:$D$1000,_xlfn.XLOOKUP($C27,Item_List_Number,Item_List,"",0),'Data Table'!$F$8:$F$1000,"Inside",'Data Table'!$H$8:$H$1000,_xlfn.XLOOKUP(DSCountry,DS_Country_List,DS_Currency_List)) -> 0 | F27: =SUMIFS('Data Table'!$J$8:$J$1000,'Data Table'!$D$8:$D$1000,_xlfn.XLOOKUP($C27,Item_List_Number,Item_List,"",0),'Data Table'!$F$8:$F$1000,"Inside",'Data Table'!$H$8:$H$1000,"<>"&_xlfn.XLOOKUP(DSCountry,DS_Country_List,DS_Currency_List)) -> 0 | G27: USD | H27: =SUMIFS('Data Table'!$J$8:$J$1000,'Data Table'!$D$8:$D$1000,_xlfn.XLOOKUP($C27,Item_List_Number,Item_List,"",0),'Data Table'!$F$8:$F$1000,"Outside") -> 0 | I27: USD
C28: 44 | D28: Games, toys and hobby-related articles | E28: =SUMIFS('Data Table'!$G$8:$G$1000,'Data Table'!$D$8:$D$1000,_xlfn.XLOOKUP($C28,Item_List_Number,Item_List,"",0),'Data Table'!$F$8:$F$1000,"Inside",'Data Table'!$H$8:$H$1000,_xlfn.XLOOKUP(DSCountry,DS_Country_List,DS_Currency_List)) -> 0 | F28: =SUMIFS('Data Table'!$J$8:$J$1000,'Data Table'!$D$8:$D$1000,_xlfn.XLOOKUP($C28,Item_List_Number,Item_List,"",0),'Data Table'!$F$8:$F$1000,"Inside",'Data Table'!$H$8:$H$1000,"<>"&_xlfn.XLOOKUP(DSCountry,DS_Country_List,DS_Currency_List)) -> 0 | G28: USD | H28: =SUMIFS('Data Table'!$J$8:$J$1000,'Data Table'!$D$8:$D$1000,_xlfn.XLOOKUP($C28,Item_List_Number,Item_List,"",0),'Data Table'!$F$8:$F$1000,"Outside") -> 0 | I28: USD
C29: 45 | D29: Garden products, plants and flowers | E29: =SUMIFS('Data Table'!$G$8:$G$1000,'Data Table'!$D$8:$D$1000,_xlfn.XLOOKUP($C29,Item_List_Number,Item_List,"",0),'Data Table'!$F$8:$F$1000,"Inside",'Data Table'!$H$8:$H$1000,_xlfn.XLOOKUP(DSCountry,DS_Country_List,DS_Currency_List)) -> 0 | F29: =SUMIFS('Data Table'!$J$8:$J$1000,'Data Table'!$D$8:$D$1000,_xlfn.XLOOKUP($C29,Item_List_Number,Item_List,"",0),'Data Table'!$F$8:$F$1000,"Inside",'Data Table'!$H$8:$H$1000,"<>"&_xlfn.XLOOKUP(DSCountry,DS_Country_List,DS_Currency_List)) -> 0 | G29: USD | H29: =SUMIFS('Data Table'!$J$8:$J$1000,'Data Table'!$D$8:$D$1000,_xlfn.XLOOKUP($C29,Item_List_Number,Item_List,"",0),'Data Table'!$F$8:$F$1000,"Outside") -> 0 | I29: USD
C30: 46 | D30: Package holidays | E30: =SUMIFS('Data Table'!$G$8:$G$1000,'Data Table'!$D$8:$D$1000,_xlfn.XLOOKUP($C30,Item_List_Number,Item_List,"",0),'Data Table'!$F$8:$F$1000,"Inside",'Data Table'!$H$8:$H$1000,_xlfn.XLOOKUP(DSCountry,DS_Country_List,DS_Currency_List)) -> 0 | F30: =SUMIFS('Data Table'!$J$8:$J$1000,'Data Table'!$D$8:$D$1000,_xlfn.XLOOKUP($C30,Item_List_Number,Item_List,"",0),'Data Table'!$F$8:$F$1000,"Inside",'Data Table'!$H$8:$H$1000,"<>"&_xlfn.XLOOKUP(DSCountry,DS_Country_List,DS_Currency_List)) -> 0 | G30: USD | H30: =SUMIFS('Data Table'!$J$8:$J$1000,'Data Table'!$D$8:$D$1000,_xlfn.XLOOKUP($C30,Item_List_Number,Item_List,"",0),'Data Table'!$F$8:$F$1000,"Outside") -> 0 | I30: USD
C31: Restaurants and Accommodation Services
C32: 47 | D32: Accommodation services | E32: =SUMIFS('Data Table'!$G$8:$G$1000,'Data Table'!$D$8:$D$1000,_xlfn.XLOOKUP($C32,Item_List_Number,Item_List,"",0),'Data Table'!$F$8:$F$1000,"Inside",'Data Table'!$H$8:$H$1000,_xlfn.XLOOKUP(DSCountry,DS_Country_List,DS_Currency_List)) -> 0 | F32: =SUMIFS('Data Table'!$J$8:$J$1000,'Data Table'!$D$8:$D$1000,_xlfn.XLOOKUP($C32,Item_List_Number,Item_List,"",0),'Data Table'!$F$8:$F$1000,"Inside",'Data Table'!$H$8:$H$1000,"<>"&_xlfn.XLOOKUP(DSCountry,DS_Country_List,DS_Currency_List)) -> 0 | G32: USD | H32: =SUMIFS('Data Table'!$J$8:$J$1000,'Data Table'!$D$8:$D$1000,_xlfn.XLOOKUP($C32,Item_List_Number,Item_List,"",0),'Data Table'!$F$8:$F$1000,"Outside") -> 0 | I32: USD
C33: Insurance and Financial Services
C34: 48 | D34: Financial services | E34: =SUMIFS('Data Table'!$G$8:$G$1000,'Data Table'!$D$8:$D$1000,_xlfn.XLOOKUP($C34,Item_List_Number,Item_List,"",0),'Data Table'!$F$8:$F$1000,"Inside",'Data Table'!$H$8:$H$1000,_xlfn.XLOOKUP(DSCountry,DS_Country_List,DS_Currency_List)) -> 0 | F34: =SUMIFS('Data Table'!$J$8:$J$1000,'Data Table'!$D$8:$D$1000,_xlfn.XLOOKUP($C34,Item_List_Number,Item_List,"",0),'Data Table'!$F$8:$F$1000,"Inside",'Data Table'!$H$8:$H$1000,"<>"&_xlfn.XLOOKUP(DSCountry,DS_Country_List,DS_Currency_List)) -> 0 | G34: USD | H34: =SUMIFS('Data Table'!$J$8:$J$1000,'Data Table'!$D$8:$D$1000,_xlfn.XLOOKUP($C34,Item_List_Number,Item_List,"",0),'Data Table'!$F$8:$F$1000,"Outside") -> 0 | I34: USD
C35: Personal Care, Social Protection and Miscellaneous Goods and Services
C36: 49a | D36: Electric appliances for personal care | E36: =SUMIFS('Data Table'!$G$8:$G$1000,'Data Table'!$D$8:$D$1000,_xlfn.XLOOKUP($C36,Item_List_Number,Item_List,"",0),'Data Table'!$F$8:$F$1000,"Inside",'Data Table'!$H$8:$H$1000,_xlfn.XLOOKUP(DSCountry,DS_Country_List,DS_Currency_List)) -> 0 | F36: =SUMIFS('Data Table'!$J$8:$J$1000,'Data Table'!$D$8:$D$1000,_xlfn.XLOOKUP($C36,Item_List_Number,Item_List,"",0),'Data Table'!$F$8:$F$1000,"Inside",'Data Table'!$H$8:$H$1000,"<>"&_xlfn.XLOOKUP(DSCountry,DS_Country_List,DS_Currency_List)) -> 0 | G36: USD | H36: =SUMIFS('Data Table'!$J$8:$J$1000,'Data Table'!$D$8:$D$1000,_xlfn.XLOOKUP($C36,Item_List_Number,Item_List,"",0),'Data Table'!$F$8:$F$1000,"Outside") -> 0 | I36: USD
C37: 49b | D37: Other appliances, articles and products for personal care | E37: =SUMIFS('Data Table'!$G$8:$G$1000,'Data Table'!$D$8:$D$1000,_xlfn.XLOOKUP($C37,Item_List_Number,Item_List,"",0),'Data Table'!$F$8:$F$1000,"Inside",'Data Table'!$H$8:$H$1000,_xlfn.XLOOKUP(DSCountry,DS_Country_List,DS_Currency_List)) -> 0 | F37: =SUMIFS('Data Table'!$J$8:$J$1000,'Data Table'!$D$8:$D$1000,_xlfn.XLOOKUP($C37,Item_List_Number,Item_List,"",0),'Data Table'!$F$8:$F$1000,"Inside",'Data Table'!$H$8:$H$1000,"<>"&_xlfn.XLOOKUP(DSCountry,DS_Country_List,DS_Currency_List)) -> 0 | G37: USD | H37: =SUMIFS('Data Table'!$J$8:$J$1000,'Data Table'!$D$8:$D$1000,_xlfn.XLOOKUP($C37,Item_List_Number,Item_List,"",0),'Data Table'!$F$8:$F$1000,"Outside") -> 0 | I37: USD
C38: 50a | D38: Social protection | E38: =SUMIFS('Data Table'!$G$8:$G$1000,'Data Table'!$D$8:$D$1000,_xlfn.XLOOKUP($C38,Item_List_Number,Item_List,"",0),'Data Table'!$F$8:$F$1000,"Inside",'Data Table'!$H$8:$H$1000,_xlfn.XLOOKUP(DSCountry,DS_Country_List,DS_Currency_List)) -> 0 | F38: =SUMIFS('Data Table'!$J$8:$J$1000,'Data Table'!$D$8:$D$1000,_xlfn.XLOOKUP($C38,Item_List_Number,Item_List,"",0),'Data Table'!$F$8:$F$1000,"Inside",'Data Table'!$H$8:$H$1000,"<>"&_xlfn.XLOOKUP(DSCountry,DS_Country_List,DS_Currency_List)) -> 0 | G38: USD | H38: =SUMIFS('Data Table'!$J$8:$J$1000,'Data Table'!$D$8:$D$1000,_xlfn.XLOOKUP($C38,Item_List_Number,Item_List,"",0),'Data Table'!$F$8:$F$1000,"Outside") -> 0 | I38: USD
C39: 50b | D39: Other personal effects | E39: =SUMIFS('Data Table'!$G$8:$G$1000,'Data Table'!$D$8:$D$1000,_xlfn.XLOOKUP($C39,Item_List_Number,Item_List,"",0),'Data Table'!$F$8:$F$1000,"Inside",'Data Table'!$H$8:$H$1000,_xlfn.XLOOKUP(DSCountry,DS_Country_List,DS_Currency_List)) -> 0 | F39: =SUMIFS('Data Table'!$J$8:$J$1000,'Data Table'!$D$8:$D$1000,_xlfn.XLOOKUP($C39,Item_List_Number,Item_List,"",0),'Data Table'!$F$8:$F$1000,"Inside",'Data Table'!$H$8:$H$1000,"<>"&_xlfn.XLOOKUP(DSCountry,DS_Country_List,DS_Currency_List)) -> 0 | G39: USD | H39: =SUMIFS('Data Table'!$J$8:$J$1000,'Data Table'!$D$8:$D$1000,_xlfn.XLOOKUP($C39,Item_List_Number,Item_List,"",0),'Data Table'!$F$8:$F$1000,"Outside") -> 0 | I39: USD
C40: 50c | D40: Other services | E40: =SUMIFS('Data Table'!$G$8:$G$1000,'Data Table'!$D$8:$D$1000,_xlfn.XLOOKUP($C40,Item_List_Number,Item_List,"",0),'Data Table'!$F$8:$F$1000,"Inside",'Data Table'!$H$8:$H$1000,_xlfn.XLOOKUP(DSCountry,DS_Country_List,DS_Currency_List)) -> 0 | F40: =SUMIFS('Data Table'!$J$8:$J$1000,'Data Table'!$D$8:$D$1000,_xlfn.XLOOKUP($C40,Item_List_Number,Item_List,"",0),'Data Table'!$F$8:$F$1000,"Inside",'Data Table'!$H$8:$H$1000,"<>"&_xlfn.XLOOKUP(DSCountry,DS_Country_List,DS_Currency_List)) -> 0 | G40: USD | H40: =SUMIFS('Data Table'!$J$8:$J$1000,'Data Table'!$D$8:$D$1000,_xlfn.XLOOKUP($C40,Item_List_Number,Item_List,"",0),'Data Table'!$F$8:$F$1000,"Outside") -> 0 | I40: USD
C41: Other
...

Sheet Infrequent Expenses
D2: ICSC Electronic Diary for Infrequent Expenditures within Last Five Years | E2: INSIDE COUNTRY OF DUTY STATION | H2: OUTSIDE COUNTRY OF DUTY STATION
E3: =IF(ISBLANK(DSCountry),"Specify country in Data Table","Amount Spent in Local Currency ("&(_xlfn.XLOOKUP(DSCountry,DS_Country_List,DS_Currency_List))&")") -> Amount Spent in Local Currency (AUD) | F3: Amount Spent in Other Currency (Expressed in USD) | H3: Amount Spent (Expressed in USD)
C4: Furnishings, Household Equipment and Routine Household Maintenance
C5: 55 | D5: Major electric and other household appliances | E5: =SUMIFS('Data Table'!$G$8:$G$1000,'Data Table'!$D$8:$D$1000,_xlfn.XLOOKUP($C5,Item_List_Number,Item_List,"",0),'Data Table'!$F$8:$F$1000,"Inside",'Data Table'!$H$8:$H$1000,_xlfn.XLOOKUP(DSCountry,DS_Country_List,DS_Currency_List)) -> 0 | F5: =SUMIFS('Data Table'!$J$8:$J$1000,'Data Table'!$D$8:$D$1000,_xlfn.XLOOKUP($C5,Item_List_Number,Item_List,"",0),'Data Table'!$F$8:$F$1000,"Inside",'Data Table'!$H$8:$H$1000,"<>"&_xlfn.XLOOKUP(DSCountry,DS_Country_List,DS_Currency_List)) -> 0 | G5: USD | H5: =SUMIFS('Data Table'!$J$8:$J$1000,'Data Table'!$D$8:$D$1000,_xlfn.XLOOKUP($C5,Item_List_Number,Item_List,"",0),'Data Table'!$F$8:$F$1000,"Outside") -> 0 | I5: USD
C6: Recreation, Sport and Culture
C7: 56 | D7: Major recreational durables | E7: =SUMIFS('Data Table'!$G$8:$G$1000,'Data Table'!$D$8:$D$1000,_xlfn.XLOOKUP($C7,Item_List_Number,Item_List,"",0),'Data Table'!$F$8:$F$1000,"Inside",'Data Table'!$H$8:$H$1000,_xlfn.XLOOKUP(DSCountry,DS_Country_List,DS_Currency_List)) -> 0 | F7: =SUMIFS('Data Table'!$J$8:$J$1000,'Data Table'!$D$8:$D$1000,_xlfn.XLOOKUP($C7,Item_List_Number,Item_List,"",0),'Data Table'!$F$8:$F$1000,"Inside",'Data Table'!$H$8:$H$1000,"<>"&_xlfn.XLOOKUP(DSCountry,DS_Country_List,DS_Currency_List)) -> 0 | G7: USD | H7: =SUMIFS('Data Table'!$J$8:$J$1000,'Data Table'!$D$8:$D$1000,_xlfn.XLOOKUP($C7,Item_List_Number,Item_List,"",0),'Data Table'!$F$8:$F$1000,"Outside") -> 0 | I7: USD
C8: Other Personal Effects
C9: 57 | D9: Jewelry and watches | E9: =SUMIFS('Data Table'!$G$8:$G$1000,'Data Table'!$D$8:$D$1000,_xlfn.XLOOKUP($C9,Item_List_Number,Item_List,"",0),'Data Table'!$F$8:$F$1000,"Inside",'Data Table'!$H$8:$H$1000,_xlfn.XLOOKUP(DSCountry,DS_Country_List,DS_Currency_List)) -> 0 | F9: =SUMIFS('Data Table'!$J$8:$J$1000,'Data Table'!$D$8:$D$1000,_xlfn.XLOOKUP($C9,Item_List_Number,Item_List,"",0),'Data Table'!$F$8:$F$1000,"Inside",'Data Table'!$H$8:$H$1000,"<>"&_xlfn.XLOOKUP(DSCountry,DS_Country_List,DS_Currency_List)) -> 0 | G9: USD | H9: =SUMIFS('Data Table'!$J$8:$J$1000,'Data Table'!$D$8:$D$1000,_xlfn.XLOOKUP($C9,Item_List_Number,Item_List,"",0),'Data Table'!$F$8:$F$1000,"Outside") -> 0 | I9: USD
C10: Transport: Purchase and Sale of Vehicles
C11: 58a | D11: Car 1 (Net of Purchase/Sale) | E11: =SUMIFS('Data Table'!$G$8:$G$1000,'Data Table'!$D$8:$D$1000,_xlfn.XLOOKUP($C11,Item_List_Number,Item_List,"",0),'Data Table'!$F$8:$F$1000,"Inside",'Data Table'!$H$8:$H$1000,_xlfn.XLOOKUP(DSCountry,DS_Country_List,DS_Currency_List)) -> 0 | F11: =SUMIFS('Data Table'!$J$8:$J$1000,'Data Table'!$D$8:$D$1000,_xlfn.XLOOKUP($C11,Item_List_Number,Item_List,"",0),'Data Table'!$F$8:$F$1000,"Inside",'Data Table'!$H$8:$H$1000,"<>"&_xlfn.XLOOKUP(DSCountry,DS_Country_List,DS_Currency_List)) -> 0 | G11: USD | H11: =SUMIFS('Data Table'!$J$8:$J$1000,'Data Table'!$D$8:$D$1000,_xlfn.XLOOKUP($C11,Item_List_Number,Item_List,"",0),'Data Table'!$F$8:$F$1000,"Outside") -> 0 | I11: USD
C12: 58b | D12: Car 2 (Net of Purchase/Sale) | E12: =SUMIFS('Data Table'!$G$8:$G$1000,'Data Table'!$D$8:$D$1000,_xlfn.XLOOKUP($C12,Item_List_Number,Item_List,"",0),'Data Table'!$F$8:$F$1000,"Inside",'Data Table'!$H$8:$H$1000,_xlfn.XLOOKUP(DSCountry,DS_Country_List,DS_Currency_List)) -> 0 | F12: =SUMIFS('Data Table'!$J$8:$J$1000,'Data Table'!$D$8:$D$1000,_xlfn.XLOOKUP($C12,Item_List_Number,Item_List,"",0),'Data Table'!$F$8:$F$1000,"Inside",'Data Table'!$H$8:$H$1000,"<>"&_xlfn.XLOOKUP(DSCountry,DS_Country_List,DS_Currency_List)) -> 0 | G12: USD | H12: =SUMIFS('Data Table'!$J$8:$J$1000,'Data Table'!$D$8:$D$1000,_xlfn.XLOOKUP($C12,Item_List_Number,Item_List,"",0),'Data Table'!$F$8:$F$1000,"Outside") -> 0 | I12: USD
C13: 59a | D13: Other vehicle 1 (Net of Purchase/Sale) | E13: =SUMIFS('Data Table'!$G$8:$G$1000,'Data Table'!$D$8:$D$1000,_xlfn.XLOOKUP($C13,Item_List_Number,Item_List,"",0),'Data Table'!$F$8:$F$1000,"Inside",'Data Table'!$H$8:$H$1000,_xlfn.XLOOKUP(DSCountry,DS_Country_List,DS_Currency_List)) -> 0 | F13: =SUMIFS('Data Table'!$J$8:$J$1000,'Data Table'!$D$8:$D$1000,_xlfn.XLOOKUP($C13,Item_List_Number,Item_List,"",0),'Data Table'!$F$8:$F$1000,"Inside",'Data Table'!$H$8:$H$1000,"<>"&_xlfn.XLOOKUP(DSCountry,DS_Country_List,DS_Currency_List)) -> 0 | G13: USD | H13: =SUMIFS('Data Table'!$J$8:$J$1000,'Data Table'!$D$8:$D$1000,_xlfn.XLOOKUP($C13,Item_List_Number,Item_List,"",0),'Data Table'!$F$8:$F$1000,"Outside") -> 0 | I13: USD
C14: 59b | D14: Other vehicle 2 (Net of Purchase/Sale) | E14: =SUMIFS('Data Table'!$G$8:$G$1000,'Data Table'!$D$8:$D$1000,_xlfn.XLOOKUP($C14,Item_List_Number,Item_List,"",0),'Data Table'!$F$8:$F$1000,"Inside",'Data Table'!$H$8:$H$1000,_xlfn.XLOOKUP(DSCountry,DS_Country_List,DS_Currency_List)) -> 0 | F14: =SUMIFS('Data Table'!$J$8:$J$1000,'Data Table'!$D$8:$D$1000,_xlfn.XLOOKUP($C14,Item_List_Number,Item_List,"",0),'Data Table'!$F$8:$F$1000,"Inside",'Data Table'!$H$8:$H$1000,"<>"&_xlfn.XLOOKUP(DSCountry,DS_Country_List,DS_Currency_List)) -> 0 | G14: USD | H14: =SUMIFS('Data Table'!$J$8:$J$1000,'Data Table'!$D$8:$D$1000,_xlfn.XLOOKUP($C14,Item_List_Number,Item_List,"",0),'Data Table'!$F$8:$F$1000,"Outside") -> 0 | I14: USD

Sheet FX Rates
B1: {='UN Treasury'!$B$1:$BQ$1} -> 46249 | C1: 46218 | D1: 46188 | E1: 46157 | F1: 46127 | G1: 46096 | H1: 46068 | I1: 46037 | J1: 46006 | K1: 45976 | L1: 45945 | M1: 45915 | N1: 45884 | O1: 45853 | P1: 45823 | Q1: 45792 | R1: 45762 | S1: 45731 | T1: 45703 | U1: 45672 | V1: 45641 | W1: 45611 | X1: 45580 | Y1: 45550 | Z1: 45519 | AA1: 45488 | AB1: 45458 | AC1: 45427 | AD1: 45397 | AE1: 45366 | AF1: 45337 | AG1: 45306 | AH1: 45275 | AI1: 45245 | AJ1: 45214 | AK1: 45184 | AL1: 45153 | AM1: 45122 | AN1: 45092 | AO1: 45061 | AP1: 45031 | AQ1: 45000 | AR1: 44972 | AS1: 44941 | AT1: 44910 | AU1: 44880 | AV1: 44848 | AW1: 44819 | AX1: 44788 | AY1: 44757 | AZ1: 44727 | BA1: 44694 | BB1: 44665 | BC1: 44635 | BD1: 44607 | BE1: 44575 | BF1: 44545 | BG1: 44515 | BH1: 44470 | BI1: 44454 | BJ1: 44409 | BK1: 44392 | BL1: 44348 | BM1: 44317 | BN1: 44301 | BO1: 44270 | BP1: 44242 | BQ1: 44211
